Traceback (most recent call last):
  File "/Library/Frameworks/Python.framework/Versions/3.10/lib/python3.10/site-packages/jupyter_cache/executors/utils.py", line 58, in single_nb_execution
    executenb(
  File "/Library/Frameworks/Python.framework/Versions/3.10/lib/python3.10/site-packages/nbclient/client.py", line 1314, in execute
    return NotebookClient(nb=nb, resources=resources, km=km, **kwargs).execute()
  File "/Library/Frameworks/Python.framework/Versions/3.10/lib/python3.10/site-packages/jupyter_core/utils/__init__.py", line 165, in wrapped
    return loop.run_until_complete(inner)
  File "/Library/Frameworks/Python.framework/Versions/3.10/lib/python3.10/asyncio/base_events.py", line 646, in run_until_complete
    return future.result()
  File "/Library/Frameworks/Python.framework/Versions/3.10/lib/python3.10/site-packages/nbclient/client.py", line 709, in async_execute
    await self.async_execute_cell(
  File "/Library/Frameworks/Python.framework/Versions/3.10/lib/python3.10/site-packages/nbclient/client.py", line 1062, in async_execute_cell
    await self._check_raise_for_error(cell, cell_index, exec_reply)
  File "/Library/Frameworks/Python.framework/Versions/3.10/lib/python3.10/site-packages/nbclient/client.py", line 918, in _check_raise_for_error
    raise CellExecutionError.from_cell_and_msg(cell, exec_reply_content)
nbclient.exceptions.CellExecutionError: An error occurred while executing the following cell:
------------------
transfer_accuracy(Xrna_integrated,Yatac_subsamp_integrated,rna['celltype'],atac_mod['celltype'],5)
------------------


[0;31m---------------------------------------------------------------------------[0m
[0;31mNameError[0m                                 Traceback (most recent call last)
Cell [0;32mIn[19], line 1[0m
[0;32m----> 1[0m [43mtransfer_accuracy[49m[43m([49m[43mXrna_integrated[49m[43m,[49m[43mYatac_subsamp_integrated[49m[43m,[49m[43mrna[49m[43m[[49m[38;5;124;43m'[39;49m[38;5;124;43mcelltype[39;49m[38;5;124;43m'[39;49m[43m][49m[43m,[49m[43matac_mod[49m[43m[[49m[38;5;124;43m'[39;49m[38;5;124;43mcelltype[39;49m[38;5;124;43m'[39;49m[43m][49m[43m,[49m[38;5;241;43m5[39;49m[43m)[49m

Cell [0;32mIn[18], line 5[0m, in [0;36mtransfer_accuracy[0;34m(domain1, domain2, type1, type2, n)[0m
[1;32m      1[0m [38;5;28;01mdef[39;00m [38;5;21mtransfer_accuracy[39m(domain1, domain2, type1, type2,n):
[1;32m      2[0m [38;5;250m	[39m[38;5;124;03m"""[39;00m
[1;32m      3[0m [38;5;124;03m	Metric from UnionCom: "Label Transfer Accuracy"[39;00m
[1;32m      4[0m [38;5;124;03m	"""[39;00m
[0;32m----> 5[0m 	knn [38;5;241m=[39m [43mKNeighborsClassifier[49m(n_neighbors[38;5;241m=[39mn)
[1;32m      6[0m 	knn[38;5;241m.[39mfit(domain2, type2)
[1;32m      7[0m 	type1_predict [38;5;241m=[39m knn[38;5;241m.[39mpredict(domain1)

[0;31mNameError[0m: name 'KNeighborsClassifier' is not defined

