Traceback (most recent call last):
  File "/Library/Frameworks/Python.framework/Versions/3.10/lib/python3.10/site-packages/jupyter_cache/executors/utils.py", line 58, in single_nb_execution
    executenb(
  File "/Library/Frameworks/Python.framework/Versions/3.10/lib/python3.10/site-packages/nbclient/client.py", line 1314, in execute
    return NotebookClient(nb=nb, resources=resources, km=km, **kwargs).execute()
  File "/Library/Frameworks/Python.framework/Versions/3.10/lib/python3.10/site-packages/jupyter_core/utils/__init__.py", line 165, in wrapped
    return loop.run_until_complete(inner)
  File "/Library/Frameworks/Python.framework/Versions/3.10/lib/python3.10/asyncio/base_events.py", line 646, in run_until_complete
    return future.result()
  File "/Library/Frameworks/Python.framework/Versions/3.10/lib/python3.10/site-packages/nbclient/client.py", line 709, in async_execute
    await self.async_execute_cell(
  File "/Library/Frameworks/Python.framework/Versions/3.10/lib/python3.10/site-packages/nbclient/client.py", line 1062, in async_execute_cell
    await self._check_raise_for_error(cell, cell_index, exec_reply)
  File "/Library/Frameworks/Python.framework/Versions/3.10/lib/python3.10/site-packages/nbclient/client.py", line 918, in _check_raise_for_error
    raise CellExecutionError.from_cell_and_msg(cell, exec_reply_content)
nbclient.exceptions.CellExecutionError: An error occurred while executing the following cell:
------------------
# l2 normalization of both datasets, which we found to help with single cell applications
adt = pd.DataFrame(normalize(adt_raw.X.transpose()))
rna = pd.DataFrame(normalize(rna_raw.X.transpose()))

# annotation of both domains
adt.index, adt.columns = samp_labels, adt_feat_labels
rna.index, rna.columns = samp_labels, rna_feat_labels
------------------


[0;31m---------------------------------------------------------------------------[0m
[0;31mValueError[0m                                Traceback (most recent call last)
Cell [0;32mIn[3], line 7[0m
[1;32m      5[0m [38;5;66;03m# annotation of both domains[39;00m
[1;32m      6[0m adt[38;5;241m.[39mindex, adt[38;5;241m.[39mcolumns [38;5;241m=[39m samp_labels, adt_feat_labels
[0;32m----> 7[0m rna[38;5;241m.[39mindex, [43mrna[49m[38;5;241;43m.[39;49m[43mcolumns[49m [38;5;241m=[39m samp_labels, rna_feat_labels

File [0;32m/Library/Frameworks/Python.framework/Versions/3.10/lib/python3.10/site-packages/pandas/core/generic.py:6216[0m, in [0;36mNDFrame.__setattr__[0;34m(self, name, value)[0m
[1;32m   6214[0m [38;5;28;01mtry[39;00m:
[1;32m   6215[0m     [38;5;28mobject[39m[38;5;241m.[39m[38;5;21m__getattribute__[39m([38;5;28mself[39m, name)
[0;32m-> 6216[0m     [38;5;28;01mreturn[39;00m [38;5;28;43mobject[39;49m[38;5;241;43m.[39;49m[38;5;21;43m__setattr__[39;49m[43m([49m[38;5;28;43mself[39;49m[43m,[49m[43m [49m[43mname[49m[43m,[49m[43m [49m[43mvalue[49m[43m)[49m
[1;32m   6217[0m [38;5;28;01mexcept[39;00m [38;5;167;01mAttributeError[39;00m:
[1;32m   6218[0m     [38;5;28;01mpass[39;00m

File [0;32mproperties.pyx:69[0m, in [0;36mpandas._libs.properties.AxisProperty.__set__[0;34m()[0m

File [0;32m/Library/Frameworks/Python.framework/Versions/3.10/lib/python3.10/site-packages/pandas/core/generic.py:767[0m, in [0;36mNDFrame._set_axis[0;34m(self, axis, labels)[0m
[1;32m    762[0m [38;5;250m[39m[38;5;124;03m"""[39;00m
[1;32m    763[0m [38;5;124;03mThis is called from the cython code when we set the `index` attribute[39;00m
[1;32m    764[0m [38;5;124;03mdirectly, e.g. `series.index = [1, 2, 3]`.[39;00m
[1;32m    765[0m [38;5;124;03m"""[39;00m
[1;32m    766[0m labels [38;5;241m=[39m ensure_index(labels)
[0;32m--> 767[0m [38;5;28;43mself[39;49m[38;5;241;43m.[39;49m[43m_mgr[49m[38;5;241;43m.[39;49m[43mset_axis[49m[43m([49m[43maxis[49m[43m,[49m[43m [49m[43mlabels[49m[43m)[49m
[1;32m    768[0m [38;5;28mself[39m[38;5;241m.[39m_clear_item_cache()

File [0;32m/Library/Frameworks/Python.framework/Versions/3.10/lib/python3.10/site-packages/pandas/core/internals/managers.py:227[0m, in [0;36mBaseBlockManager.set_axis[0;34m(self, axis, new_labels)[0m
[1;32m    225[0m [38;5;28;01mdef[39;00m [38;5;21mset_axis[39m([38;5;28mself[39m, axis: AxisInt, new_labels: Index) [38;5;241m-[39m[38;5;241m>[39m [38;5;28;01mNone[39;00m:
[1;32m    226[0m     [38;5;66;03m# Caller is responsible for ensuring we have an Index object.[39;00m
[0;32m--> 227[0m     [38;5;28;43mself[39;49m[38;5;241;43m.[39;49m[43m_validate_set_axis[49m[43m([49m[43maxis[49m[43m,[49m[43m [49m[43mnew_labels[49m[43m)[49m
[1;32m    228[0m     [38;5;28mself[39m[38;5;241m.[39maxes[axis] [38;5;241m=[39m new_labels

File [0;32m/Library/Frameworks/Python.framework/Versions/3.10/lib/python3.10/site-packages/pandas/core/internals/base.py:85[0m, in [0;36mDataManager._validate_set_axis[0;34m(self, axis, new_labels)[0m
[1;32m     82[0m     [38;5;28;01mpass[39;00m
[1;32m     84[0m [38;5;28;01melif[39;00m new_len [38;5;241m!=[39m old_len:
[0;32m---> 85[0m     [38;5;28;01mraise[39;00m [38;5;167;01mValueError[39;00m(
[1;32m     86[0m         [38;5;124mf[39m[38;5;124m"[39m[38;5;124mLength mismatch: Expected axis has [39m[38;5;132;01m{[39;00mold_len[38;5;132;01m}[39;00m[38;5;124m elements, new [39m[38;5;124m"[39m
[1;32m     87[0m         [38;5;124mf[39m[38;5;124m"[39m[38;5;124mvalues have [39m[38;5;132;01m{[39;00mnew_len[38;5;132;01m}[39;00m[38;5;124m elements[39m[38;5;124m"[39m
[1;32m     88[0m     )

[0;31mValueError[0m: Length mismatch: Expected axis has 25 elements, new values have 24 elements

